[2025-08-10T14:56:33.311+0000] {taskinstance.py:1956} INFO - Dependencies all met for dep_context=non-requeueable deps ti=<TaskInstance: train_with_dvc.dvc_pull manual__2025-08-10T14:56:32.437439+00:00 [queued]>
[2025-08-10T14:56:33.333+0000] {taskinstance.py:1956} INFO - Dependencies all met for dep_context=requeueable deps ti=<TaskInstance: train_with_dvc.dvc_pull manual__2025-08-10T14:56:32.437439+00:00 [queued]>
[2025-08-10T14:56:33.334+0000] {taskinstance.py:2170} INFO - Starting attempt 1 of 1
[2025-08-10T14:56:33.378+0000] {taskinstance.py:2191} INFO - Executing <Task(BashOperator): dvc_pull> on 2025-08-10 14:56:32.437439+00:00
[2025-08-10T14:56:33.387+0000] {standard_task_runner.py:60} INFO - Started process 794 to run task
[2025-08-10T14:56:33.393+0000] {standard_task_runner.py:87} INFO - Running: ['***', 'tasks', 'run', 'train_with_dvc', 'dvc_pull', 'manual__2025-08-10T14:56:32.437439+00:00', '--job-id', '75', '--raw', '--subdir', 'DAGS_FOLDER/train_with_dvc.py', '--cfg-path', '/tmp/tmpoxlmxxsp']
[2025-08-10T14:56:33.400+0000] {standard_task_runner.py:88} INFO - Job 75: Subtask dvc_pull
[2025-08-10T14:56:33.603+0000] {task_command.py:423} INFO - Running <TaskInstance: train_with_dvc.dvc_pull manual__2025-08-10T14:56:32.437439+00:00 [running]> on host 1a0a448a8cb5
[2025-08-10T14:56:33.748+0000] {taskinstance.py:2480} INFO - Exporting env vars: AIRFLOW_CTX_DAG_OWNER='***' AIRFLOW_CTX_DAG_ID='train_with_dvc' AIRFLOW_CTX_TASK_ID='dvc_pull' AIRFLOW_CTX_EXECUTION_DATE='2025-08-10T14:56:32.437439+00:00' AIRFLOW_CTX_TRY_NUMBER='1' AIRFLOW_CTX_DAG_RUN_ID='manual__2025-08-10T14:56:32.437439+00:00'
[2025-08-10T14:56:33.750+0000] {subprocess.py:63} INFO - Tmp dir root location: /tmp
[2025-08-10T14:56:33.752+0000] {subprocess.py:75} INFO - Running command: ['/usr/bin/bash', '-c', 'cd /opt/***/project && dvc pull']
[2025-08-10T14:56:33.766+0000] {subprocess.py:86} INFO - Output:
[2025-08-10T14:56:33.779+0000] {subprocess.py:93} INFO - /usr/bin/bash: line 1: dvc: command not found
[2025-08-10T14:56:33.780+0000] {subprocess.py:97} INFO - Command exited with return code 127
[2025-08-10T14:56:33.797+0000] {taskinstance.py:2698} ERROR - Task failed with exception
Traceback (most recent call last):
  File "/home/airflow/.local/lib/python3.10/site-packages/airflow/models/taskinstance.py", line 433, in _execute_task
    result = execute_callable(context=context, **execute_callable_kwargs)
  File "/home/airflow/.local/lib/python3.10/site-packages/airflow/operators/bash.py", line 212, in execute
    raise AirflowException(
airflow.exceptions.AirflowException: Bash command failed. The command returned a non-zero exit code 127.
[2025-08-10T14:56:33.802+0000] {taskinstance.py:1138} INFO - Marking task as FAILED. dag_id=train_with_dvc, task_id=dvc_pull, execution_date=20250810T145632, start_date=20250810T145633, end_date=20250810T145633
[2025-08-10T14:56:33.824+0000] {standard_task_runner.py:107} ERROR - Failed to execute job 75 for task dvc_pull (Bash command failed. The command returned a non-zero exit code 127.; 794)
[2025-08-10T14:56:33.850+0000] {local_task_job_runner.py:234} INFO - Task exited with return code 1
[2025-08-10T14:56:33.878+0000] {taskinstance.py:3280} INFO - 0 downstream tasks scheduled from follow-on schedule check
