[2025-08-07T13:44:50.654+0000] {taskinstance.py:1956} INFO - Dependencies all met for dep_context=non-requeueable deps ti=<TaskInstance: ml_pipeline.model_training manual__2025-08-07T13:39:01.223976+00:00 [queued]>
[2025-08-07T13:44:50.665+0000] {taskinstance.py:1956} INFO - Dependencies all met for dep_context=requeueable deps ti=<TaskInstance: ml_pipeline.model_training manual__2025-08-07T13:39:01.223976+00:00 [queued]>
[2025-08-07T13:44:50.666+0000] {taskinstance.py:2170} INFO - Starting attempt 2 of 2
[2025-08-07T13:44:50.682+0000] {taskinstance.py:2191} INFO - Executing <Task(PythonOperator): model_training> on 2025-08-07 13:39:01.223976+00:00
[2025-08-07T13:44:50.690+0000] {standard_task_runner.py:60} INFO - Started process 2427 to run task
[2025-08-07T13:44:50.694+0000] {standard_task_runner.py:87} INFO - Running: ['***', 'tasks', 'run', 'ml_pipeline', 'model_training', 'manual__2025-08-07T13:39:01.223976+00:00', '--job-id', '13', '--raw', '--subdir', 'DAGS_FOLDER/ml_pipeline.py', '--cfg-path', '/tmp/tmp0us9o_hl']
[2025-08-07T13:44:50.697+0000] {standard_task_runner.py:88} INFO - Job 13: Subtask model_training
[2025-08-07T13:44:50.778+0000] {task_command.py:423} INFO - Running <TaskInstance: ml_pipeline.model_training manual__2025-08-07T13:39:01.223976+00:00 [running]> on host f5d1166de0f2
[2025-08-07T13:44:50.888+0000] {taskinstance.py:2480} INFO - Exporting env vars: AIRFLOW_CTX_DAG_OWNER='sarah' AIRFLOW_CTX_DAG_ID='ml_pipeline' AIRFLOW_CTX_TASK_ID='model_training' AIRFLOW_CTX_EXECUTION_DATE='2025-08-07T13:39:01.223976+00:00' AIRFLOW_CTX_TRY_NUMBER='2' AIRFLOW_CTX_DAG_RUN_ID='manual__2025-08-07T13:39:01.223976+00:00'
[2025-08-07T13:45:23.100+0000] {logging_mixin.py:188} INFO - ‚ùå Subprocess failed!
[2025-08-07T13:45:23.101+0000] {logging_mixin.py:188} INFO - ‚ö†Ô∏è STDOUT:
[2025-08-07T13:45:23.102+0000] {logging_mixin.py:188} INFO -  Fitting 3 folds for each of 10 candidates, totalling 30 fits
[2025-08-07T13:45:23.102+0000] {logging_mixin.py:188} INFO - ‚ö†Ô∏è STDERR:
[2025-08-07T13:45:23.103+0000] {logging_mixin.py:188} INFO -  2025-08-07 13:44:53,491 - training.utils.common - INFO - YAML charg√© : /opt/***/project/config/config.yaml
2025-08-07 13:44:53,502 - training.utils.common - INFO - YAML charg√© : /opt/***/project/config/params.yaml
2025-08-07 13:44:53,505 - training.utils.common - INFO - R√©pertoire cr√©√© ou existant : /opt/***/project/models
2025-08-07 13:44:53,507 - training.utils.common - INFO - R√©pertoire cr√©√© ou existant : /opt/***/project/models
2025-08-07 13:44:54,328 - __main__ - INFO - Loaded processed data: /opt/***/project/data/processed/clean_data.csv (shape=(108060, 14))
2025-08-07 13:44:54,350 - __main__ - INFO - Split data: train_shape=(86448, 11), test_shape=(21612, 11)
2025/08/07 13:44:54 WARNING mlflow.utils.git_utils: Failed to import Git (the Git executable is probably not on your PATH), so Git SHA is not available. Error: Failed to initialize: Bad git executable.
The git executable must be specified in one of the following ways:
    - be included in your $PATH
    - be set via $GIT_PYTHON_GIT_EXECUTABLE
    - explicitly set via git.refresh(<full-path-to-git-executable>)

All git commands will error until this is rectified.

This initial message can be silenced or aggravated in the future by setting the
$GIT_PYTHON_REFRESH environment variable. Use one of the following values:
    - quiet|q|silence|s|silent|none|n|0: for no message or exception
    - warn|w|warning|log|l|1: for a warning message (logging level CRITICAL, displayed by default)
    - error|e|exception|raise|r|2: for a raised exception

Example:
    export GIT_PYTHON_REFRESH=quiet

2025-08-07 13:44:54,738 - __main__ - INFO - Starting hyperparameter search and training.
2025-08-07 13:45:04,351 - __main__ - INFO - Best params: {'colsample_bytree': 0.9219644132807024, 'gamma': 0.06692515264078093, 'learning_rate': 0.19307895078298942, 'max_depth': 5, 'n_estimators': 86, 'subsample': 0.6271914913054505}
2025-08-07 13:45:04,352 - __main__ - INFO - R^2 score: 0.9998
Registered model 'PriceFixerModel' already exists. Creating a new version of this model...
2025/08/07 13:45:14 INFO mlflow.store.model_registry.abstract_store: Waiting up to 300 seconds for model version to finish creation. Model name: PriceFixerModel, version 23
Created version '23' of model 'PriceFixerModel'.
2025/08/07 13:45:21 INFO mlflow.tracking._tracking_service.client: üèÉ View run XGBoost_RandSearch at: https://dagshub.com/SamMebarek/mlops-som.mlflow/#/experiments/0/runs/7e6151b498184469b12b1f930d24c38a.
2025/08/07 13:45:21 INFO mlflow.tracking._tracking_service.client: üß™ View experiment at: https://dagshub.com/SamMebarek/mlops-som.mlflow/#/experiments/0.
Traceback (most recent call last):
  File "/usr/local/lib/python3.8/runpy.py", line 194, in _run_module_as_main
    return _run_code(code, main_globals, None,
  File "/usr/local/lib/python3.8/runpy.py", line 87, in _run_code
    exec(code, run_globals)
  File "/opt/***/project/src/training/components/train.py", line 134, in <module>
    run_training(args.config, args.params)
  File "/opt/***/project/src/training/components/train.py", line 125, in run_training
    repo.save(search.best_estimator_)
  File "/opt/***/project/src/training/repository/repository.py", line 42, in save
    joblib.dump(model, str(self.model_path))
  File "/home/***/.local/lib/python3.8/site-packages/joblib/numpy_pickle.py", line 552, in dump
    with open(filename, 'wb') as f:
PermissionError: [Errno 13] Permission denied: '/opt/***/project/models/xgb_model.pkl'
[2025-08-07T13:45:23.104+0000] {taskinstance.py:2698} ERROR - Task failed with exception
Traceback (most recent call last):
  File "/home/airflow/.local/lib/python3.8/site-packages/airflow/models/taskinstance.py", line 433, in _execute_task
    result = execute_callable(context=context, **execute_callable_kwargs)
  File "/home/airflow/.local/lib/python3.8/site-packages/airflow/operators/python.py", line 199, in execute
    return_value = self.execute_callable()
  File "/home/airflow/.local/lib/python3.8/site-packages/airflow/operators/python.py", line 216, in execute_callable
    return self.python_callable(*self.op_args, **self.op_kwargs)
  File "/opt/airflow/dags/ml_pipeline.py", line 34, in run_training
    result = subprocess.run(
  File "/usr/local/lib/python3.8/subprocess.py", line 516, in run
    raise CalledProcessError(retcode, process.args,
subprocess.CalledProcessError: Command '['python', '-m', 'training.components.train', '--config', '/opt/airflow/project/config/config.yaml', '--params', '/opt/airflow/project/config/params.yaml']' returned non-zero exit status 1.
[2025-08-07T13:45:23.121+0000] {taskinstance.py:1138} INFO - Marking task as FAILED. dag_id=ml_pipeline, task_id=model_training, execution_date=20250807T133901, start_date=20250807T134450, end_date=20250807T134523
[2025-08-07T13:45:23.143+0000] {standard_task_runner.py:107} ERROR - Failed to execute job 13 for task model_training (Command '['python', '-m', 'training.components.train', '--config', '/opt/airflow/project/config/config.yaml', '--params', '/opt/airflow/project/config/params.yaml']' returned non-zero exit status 1.; 2427)
[2025-08-07T13:45:23.186+0000] {local_task_job_runner.py:234} INFO - Task exited with return code 1
[2025-08-07T13:45:23.205+0000] {taskinstance.py:3280} INFO - 0 downstream tasks scheduled from follow-on schedule check
