[2025-08-17T14:29:59.588+0000] {taskinstance.py:1956} INFO - Dependencies all met for dep_context=non-requeueable deps ti=<TaskInstance: ml_pipeline.reload_model manual__2025-08-17T14:23:34.939133+00:00 [queued]>
[2025-08-17T14:29:59.608+0000] {taskinstance.py:1956} INFO - Dependencies all met for dep_context=requeueable deps ti=<TaskInstance: ml_pipeline.reload_model manual__2025-08-17T14:23:34.939133+00:00 [queued]>
[2025-08-17T14:29:59.609+0000] {taskinstance.py:2170} INFO - Starting attempt 2 of 2
[2025-08-17T14:29:59.636+0000] {taskinstance.py:2191} INFO - Executing <Task(PythonOperator): reload_model> on 2025-08-17 14:23:34.939133+00:00
[2025-08-17T14:29:59.646+0000] {standard_task_runner.py:60} INFO - Started process 1786 to run task
[2025-08-17T14:29:59.652+0000] {standard_task_runner.py:87} INFO - Running: ['***', 'tasks', 'run', 'ml_pipeline', 'reload_model', 'manual__2025-08-17T14:23:34.939133+00:00', '--job-id', '145', '--raw', '--subdir', 'DAGS_FOLDER/ml_pipeline.py', '--cfg-path', '/tmp/tmpbmoxh_lm']
[2025-08-17T14:29:59.657+0000] {standard_task_runner.py:88} INFO - Job 145: Subtask reload_model
[2025-08-17T14:29:59.761+0000] {task_command.py:423} INFO - Running <TaskInstance: ml_pipeline.reload_model manual__2025-08-17T14:23:34.939133+00:00 [running]> on host e9fdf47702ac
[2025-08-17T14:29:59.877+0000] {taskinstance.py:2480} INFO - Exporting env vars: AIRFLOW_CTX_DAG_OWNER='sarah' AIRFLOW_CTX_DAG_ID='ml_pipeline' AIRFLOW_CTX_TASK_ID='reload_model' AIRFLOW_CTX_EXECUTION_DATE='2025-08-17T14:23:34.939133+00:00' AIRFLOW_CTX_TRY_NUMBER='2' AIRFLOW_CTX_DAG_RUN_ID='manual__2025-08-17T14:23:34.939133+00:00'
[2025-08-17T14:29:59.943+0000] {taskinstance.py:2698} ERROR - Task failed with exception
Traceback (most recent call last):
  File "/home/airflow/.local/lib/python3.10/site-packages/airflow/models/taskinstance.py", line 433, in _execute_task
    result = execute_callable(context=context, **execute_callable_kwargs)
  File "/home/airflow/.local/lib/python3.10/site-packages/airflow/operators/python.py", line 199, in execute
    return_value = self.execute_callable()
  File "/home/airflow/.local/lib/python3.10/site-packages/airflow/operators/python.py", line 216, in execute_callable
    return self.python_callable(*self.op_args, **self.op_kwargs)
  File "/opt/airflow/dags/ml_pipeline.py", line 159, in reload_model_via_gateway
    raise RuntimeError(f"Reload failed: {r2.status_code} {r2.text}")
RuntimeError: Reload failed: 503 {"detail":"Inference service unavailable"}
[2025-08-17T14:29:59.965+0000] {taskinstance.py:1138} INFO - Marking task as FAILED. dag_id=ml_pipeline, task_id=reload_model, execution_date=20250817T142334, start_date=20250817T142959, end_date=20250817T142959
[2025-08-17T14:29:59.983+0000] {standard_task_runner.py:107} ERROR - Failed to execute job 145 for task reload_model (Reload failed: 503 {"detail":"Inference service unavailable"}; 1786)
[2025-08-17T14:30:00.028+0000] {local_task_job_runner.py:234} INFO - Task exited with return code 1
[2025-08-17T14:30:00.074+0000] {taskinstance.py:3280} INFO - 0 downstream tasks scheduled from follow-on schedule check
