[2025-08-09T10:00:32.699+0000] {taskinstance.py:1956} INFO - Dependencies all met for dep_context=non-requeueable deps ti=<TaskInstance: ml_pipeline.model_training manual__2025-08-09T10:00:15.227324+00:00 [queued]>
[2025-08-09T10:00:32.712+0000] {taskinstance.py:1956} INFO - Dependencies all met for dep_context=requeueable deps ti=<TaskInstance: ml_pipeline.model_training manual__2025-08-09T10:00:15.227324+00:00 [queued]>
[2025-08-09T10:00:32.713+0000] {taskinstance.py:2170} INFO - Starting attempt 1 of 2
[2025-08-09T10:00:32.741+0000] {taskinstance.py:2191} INFO - Executing <Task(PythonOperator): model_training> on 2025-08-09 10:00:15.227324+00:00
[2025-08-09T10:00:32.751+0000] {standard_task_runner.py:60} INFO - Started process 197 to run task
[2025-08-09T10:00:32.758+0000] {standard_task_runner.py:87} INFO - Running: ['***', 'tasks', 'run', 'ml_pipeline', 'model_training', 'manual__2025-08-09T10:00:15.227324+00:00', '--job-id', '31', '--raw', '--subdir', 'DAGS_FOLDER/ml_pipeline.py', '--cfg-path', '/tmp/tmpf759ue3c']
[2025-08-09T10:00:32.762+0000] {standard_task_runner.py:88} INFO - Job 31: Subtask model_training
[2025-08-09T10:00:32.893+0000] {task_command.py:423} INFO - Running <TaskInstance: ml_pipeline.model_training manual__2025-08-09T10:00:15.227324+00:00 [running]> on host 06332701d606
[2025-08-09T10:00:33.212+0000] {taskinstance.py:2480} INFO - Exporting env vars: AIRFLOW_CTX_DAG_OWNER='sarah' AIRFLOW_CTX_DAG_ID='ml_pipeline' AIRFLOW_CTX_TASK_ID='model_training' AIRFLOW_CTX_EXECUTION_DATE='2025-08-09T10:00:15.227324+00:00' AIRFLOW_CTX_TRY_NUMBER='1' AIRFLOW_CTX_DAG_RUN_ID='manual__2025-08-09T10:00:15.227324+00:00'
[2025-08-09T10:00:54.116+0000] {logging_mixin.py:188} INFO - STDOUT:
[2025-08-09T10:00:54.117+0000] {logging_mixin.py:188} INFO -  Fitting 3 folds for each of 10 candidates, totalling 30 fits
üèÉ View run XGBoost_RandSearch at: https://dagshub.com/SamMebarek/mlops-som.mlflow/#/experiments/0/runs/73dda7fc4c5b4b37884338530e6fb7d8
üß™ View experiment at: https://dagshub.com/SamMebarek/mlops-som.mlflow/#/experiments/0
[2025-08-09T10:00:54.117+0000] {logging_mixin.py:188} INFO - STDERR:
[2025-08-09T10:00:54.118+0000] {logging_mixin.py:188} INFO -  2025-08-09 10:00:37,396 - training.utils.common - INFO - YAML charg√© : /opt/***/project/config/config.yaml
2025-08-09 10:00:37,404 - training.utils.common - INFO - YAML charg√© : /opt/***/project/config/params.yaml
2025-08-09 10:00:37,407 - training.utils.common - INFO - R√©pertoire cr√©√© ou existant : /opt/***/project/models
2025-08-09 10:00:37,409 - training.utils.common - INFO - R√©pertoire cr√©√© ou existant : /opt/***/project/models
2025-08-09 10:00:38,134 - __main__ - INFO - Loaded processed data: /opt/***/project/data/processed/clean_data.csv (shape=(108060, 14))
2025-08-09 10:00:38,158 - __main__ - INFO - Split data: train_shape=(86448, 11), test_shape=(21612, 11)
2025/08/09 10:00:38 WARNING mlflow.utils.git_utils: Failed to import Git (the Git executable is probably not on your PATH), so Git SHA is not available. Error: Failed to initialize: Bad git executable.
The git executable must be specified in one of the following ways:
    - be included in your $PATH
    - be set via $GIT_PYTHON_GIT_EXECUTABLE
    - explicitly set via git.refresh(<full-path-to-git-executable>)

All git commands will error until this is rectified.

This initial message can be silenced or aggravated in the future by setting the
$GIT_PYTHON_REFRESH environment variable. Use one of the following values:
    - quiet|q|silence|s|silent|none|n|0: for no message or exception
    - warn|w|warning|log|l|1: for a warning message (logging level CRITICAL, displayed by default)
    - error|e|exception|raise|r|2: for a raised exception

Example:
    export GIT_PYTHON_REFRESH=quiet

2025-08-09 10:00:38,518 - __main__ - INFO - Starting hyperparameter search and training.
2025-08-09 10:00:50,785 - __main__ - INFO - Best params: {'colsample_bytree': 0.9219644132807024, 'gamma': 0.06692515264078093, 'learning_rate': 0.19307895078298942, 'max_depth': 5, 'n_estimators': 86, 'subsample': 0.6271914913054505}
2025-08-09 10:00:50,785 - __main__ - INFO - R^2 score: 0.9998
2025/08/09 10:00:52 WARNING mlflow.models.model: `artifact_path` is deprecated. Please use `name` instead.
2025-08-09 10:00:53,100 - __main__ - ERROR - Training failed: INTERNAL_ERROR: Response: {'error': 'unsupported endpoint, please contact support@dagshub.com'}
Traceback (most recent call last):
  File "/opt/***/project/src/training/components/train.py", line 165, in run_training
    mlflow.sklearn.log_model(
  File "/home/***/.local/lib/python3.10/site-packages/mlflow/sklearn/__init__.py", line 426, in log_model
    return Model.log(
  File "/home/***/.local/lib/python3.10/site-packages/mlflow/models/model.py", line 1166, in log
    model = _create_logged_model(
  File "/home/***/.local/lib/python3.10/site-packages/mlflow/tracking/fluent.py", line 2282, in _create_logged_model
    return MlflowClient()._create_logged_model(
  File "/home/***/.local/lib/python3.10/site-packages/mlflow/tracking/client.py", line 5379, in _create_logged_model
    return self._tracking_client.create_logged_model(
  File "/home/***/.local/lib/python3.10/site-packages/mlflow/telemetry/track.py", line 22, in wrapper
    return func(*args, **kwargs)
  File "/home/***/.local/lib/python3.10/site-packages/mlflow/tracking/_tracking_service/client.py", line 841, in create_logged_model
    return self.store.create_logged_model(
  File "/home/***/.local/lib/python3.10/site-packages/mlflow/store/tracking/rest_store.py", line 823, in create_logged_model
    response_proto = self._call_endpoint(CreateLoggedModel, req_body)
  File "/home/***/.local/lib/python3.10/site-packages/mlflow/store/tracking/rest_store.py", line 133, in _call_endpoint
    return call_endpoint(
  File "/home/***/.local/lib/python3.10/site-packages/mlflow/utils/rest_utils.py", line 553, in call_endpoint
    response = verify_rest_response(response, endpoint)
  File "/home/***/.local/lib/python3.10/site-packages/mlflow/utils/rest_utils.py", line 308, in verify_rest_response
    raise RestException(json.loads(response.text))
mlflow.exceptions.RestException: INTERNAL_ERROR: Response: {'error': 'unsupported endpoint, please contact support@dagshub.com'}
2025-08-09 10:00:53,145 - __main__ - INFO - Pushed metrics to Pushgateway (http://pushgateway:9091) status=0 duration_s=15.751 rows=108060 r2=0.9997696380635521 artifact_bytes=0
Traceback (most recent call last):
  File "/usr/local/lib/python3.10/runpy.py", line 196, in _run_module_as_main
    return _run_code(code, main_globals, None,
  File "/usr/local/lib/python3.10/runpy.py", line 86, in _run_code
    exec(code, run_globals)
  File "/opt/***/project/src/training/components/train.py", line 206, in <module>
    run_training(args.config, args.params)
  File "/opt/***/project/src/training/components/train.py", line 165, in run_training
    mlflow.sklearn.log_model(
  File "/home/***/.local/lib/python3.10/site-packages/mlflow/sklearn/__init__.py", line 426, in log_model
    return Model.log(
  File "/home/***/.local/lib/python3.10/site-packages/mlflow/models/model.py", line 1166, in log
    model = _create_logged_model(
  File "/home/***/.local/lib/python3.10/site-packages/mlflow/tracking/fluent.py", line 2282, in _create_logged_model
    return MlflowClient()._create_logged_model(
  File "/home/***/.local/lib/python3.10/site-packages/mlflow/tracking/client.py", line 5379, in _create_logged_model
    return self._tracking_client.create_logged_model(
  File "/home/***/.local/lib/python3.10/site-packages/mlflow/telemetry/track.py", line 22, in wrapper
    return func(*args, **kwargs)
  File "/home/***/.local/lib/python3.10/site-packages/mlflow/tracking/_tracking_service/client.py", line 841, in create_logged_model
    return self.store.create_logged_model(
  File "/home/***/.local/lib/python3.10/site-packages/mlflow/store/tracking/rest_store.py", line 823, in create_logged_model
    response_proto = self._call_endpoint(CreateLoggedModel, req_body)
  File "/home/***/.local/lib/python3.10/site-packages/mlflow/store/tracking/rest_store.py", line 133, in _call_endpoint
    return call_endpoint(
  File "/home/***/.local/lib/python3.10/site-packages/mlflow/utils/rest_utils.py", line 553, in call_endpoint
    response = verify_rest_response(response, endpoint)
  File "/home/***/.local/lib/python3.10/site-packages/mlflow/utils/rest_utils.py", line 308, in verify_rest_response
    raise RestException(json.loads(response.text))
mlflow.exceptions.RestException: INTERNAL_ERROR: Response: {'error': 'unsupported endpoint, please contact support@dagshub.com'}
[2025-08-09T10:00:54.119+0000] {taskinstance.py:2698} ERROR - Task failed with exception
Traceback (most recent call last):
  File "/home/airflow/.local/lib/python3.10/site-packages/airflow/models/taskinstance.py", line 433, in _execute_task
    result = execute_callable(context=context, **execute_callable_kwargs)
  File "/home/airflow/.local/lib/python3.10/site-packages/airflow/operators/python.py", line 199, in execute
    return_value = self.execute_callable()
  File "/home/airflow/.local/lib/python3.10/site-packages/airflow/operators/python.py", line 216, in execute_callable
    return self.python_callable(*self.op_args, **self.op_kwargs)
  File "/opt/airflow/dags/ml_pipeline.py", line 62, in run_training
    raise subprocess.CalledProcessError(res.returncode, res.args, res.stdout, res.stderr)
subprocess.CalledProcessError: Command '['/usr/local/bin/python', '-m', 'training.components.train', '--config', '/opt/airflow/project/config/config.yaml', '--params', '/opt/airflow/project/config/params.yaml']' returned non-zero exit status 1.
[2025-08-09T10:00:54.131+0000] {taskinstance.py:1138} INFO - Marking task as UP_FOR_RETRY. dag_id=ml_pipeline, task_id=model_training, execution_date=20250809T100015, start_date=20250809T100032, end_date=20250809T100054
[2025-08-09T10:00:54.148+0000] {standard_task_runner.py:107} ERROR - Failed to execute job 31 for task model_training (Command '['/usr/local/bin/python', '-m', 'training.components.train', '--config', '/opt/airflow/project/config/config.yaml', '--params', '/opt/airflow/project/config/params.yaml']' returned non-zero exit status 1.; 197)
[2025-08-09T10:00:54.184+0000] {local_task_job_runner.py:234} INFO - Task exited with return code 1
[2025-08-09T10:00:54.210+0000] {taskinstance.py:3280} INFO - 0 downstream tasks scheduled from follow-on schedule check
