[2025-06-24T10:24:39.273+0000] {taskinstance.py:1956} INFO - Dependencies all met for dep_context=non-requeueable deps ti=<TaskInstance: ml_pipeline.data_ingestion manual__2025-06-24T10:24:15.849188+00:00 [queued]>
[2025-06-24T10:24:39.339+0000] {taskinstance.py:1956} INFO - Dependencies all met for dep_context=requeueable deps ti=<TaskInstance: ml_pipeline.data_ingestion manual__2025-06-24T10:24:15.849188+00:00 [queued]>
[2025-06-24T10:24:39.352+0000] {taskinstance.py:2170} INFO - Starting attempt 3 of 4
[2025-06-24T10:24:39.423+0000] {taskinstance.py:2191} INFO - Executing <Task(PythonOperator): data_ingestion> on 2025-06-24 10:24:15.849188+00:00
[2025-06-24T10:24:39.446+0000] {standard_task_runner.py:60} INFO - Started process 442 to run task
[2025-06-24T10:24:39.464+0000] {standard_task_runner.py:87} INFO - Running: ['***', 'tasks', 'run', 'ml_pipeline', 'data_ingestion', 'manual__2025-06-24T10:24:15.849188+00:00', '--job-id', '10', '--raw', '--subdir', 'DAGS_FOLDER/ml_pipeline.py', '--cfg-path', '/tmp/tmpne4vy09p']
[2025-06-24T10:24:39.479+0000] {standard_task_runner.py:88} INFO - Job 10: Subtask data_ingestion
[2025-06-24T10:24:39.807+0000] {task_command.py:423} INFO - Running <TaskInstance: ml_pipeline.data_ingestion manual__2025-06-24T10:24:15.849188+00:00 [running]> on host 3fe363fae776
[2025-06-24T10:24:41.156+0000] {taskinstance.py:2480} INFO - Exporting env vars: AIRFLOW_CTX_DAG_OWNER='sarah' AIRFLOW_CTX_DAG_ID='ml_pipeline' AIRFLOW_CTX_TASK_ID='data_ingestion' AIRFLOW_CTX_EXECUTION_DATE='2025-06-24T10:24:15.849188+00:00' AIRFLOW_CTX_TRY_NUMBER='3' AIRFLOW_CTX_DAG_RUN_ID='manual__2025-06-24T10:24:15.849188+00:00'
[2025-06-24T10:24:50.579+0000] {local_task_job_runner.py:302} WARNING - State of this instance has been externally set to up_for_retry. Terminating instance.
[2025-06-24T10:24:50.594+0000] {process_utils.py:131} INFO - Sending 15 to group 442. PIDs of all processes in the group: [443, 442]
[2025-06-24T10:24:50.594+0000] {process_utils.py:86} INFO - Sending the signal 15 to group 442
[2025-06-24T10:24:50.595+0000] {taskinstance.py:2450} ERROR - Received SIGTERM. Terminating subprocesses.
[2025-06-24T10:24:50.626+0000] {process_utils.py:79} INFO - Process psutil.Process(pid=443, status='terminated', started='10:24:39') (443) terminated with exit code None
[2025-06-24T10:24:50.642+0000] {taskinstance.py:2698} ERROR - Task failed with exception
Traceback (most recent call last):
  File "/home/airflow/.local/lib/python3.8/site-packages/airflow/models/taskinstance.py", line 433, in _execute_task
    result = execute_callable(context=context, **execute_callable_kwargs)
  File "/home/airflow/.local/lib/python3.8/site-packages/airflow/operators/python.py", line 199, in execute
    return_value = self.execute_callable()
  File "/home/airflow/.local/lib/python3.8/site-packages/airflow/operators/python.py", line 216, in execute_callable
    return self.python_callable(*self.op_args, **self.op_kwargs)
  File "/opt/airflow/dags/ml_pipeline.py", line 19, in run_ingestion
    subprocess.run(
  File "/usr/local/lib/python3.8/subprocess.py", line 495, in run
    stdout, stderr = process.communicate(input, timeout=timeout)
  File "/usr/local/lib/python3.8/subprocess.py", line 1020, in communicate
    self.wait()
  File "/usr/local/lib/python3.8/subprocess.py", line 1083, in wait
    return self._wait(timeout=timeout)
  File "/usr/local/lib/python3.8/subprocess.py", line 1822, in _wait
    (pid, sts) = self._try_wait(0)
  File "/usr/local/lib/python3.8/subprocess.py", line 1780, in _try_wait
    (pid, sts) = os.waitpid(self.pid, wait_flags)
  File "/home/airflow/.local/lib/python3.8/site-packages/airflow/models/taskinstance.py", line 2452, in signal_handler
    raise AirflowException("Task received SIGTERM signal")
airflow.exceptions.AirflowException: Task received SIGTERM signal
[2025-06-24T10:24:50.670+0000] {taskinstance.py:1138} INFO - Marking task as FAILED. dag_id=ml_pipeline, task_id=data_ingestion, execution_date=20250624T102415, start_date=20250624T102439, end_date=20250624T102450
[2025-06-24T10:24:50.745+0000] {standard_task_runner.py:107} ERROR - Failed to execute job 10 for task data_ingestion (Task received SIGTERM signal; 442)
[2025-06-24T10:24:50.800+0000] {process_utils.py:79} INFO - Process psutil.Process(pid=442, status='terminated', exitcode=1, started='10:24:38') (442) terminated with exit code 1
